2021-03-02 17:47:21,214   20404     INFO test_runner.py(154) - 预计并发线程数：2
2021-03-02 17:47:22,224   16040     INFO result.py(65) - 开始测试： test_login.test_login_demo (unittest.loader._FailedTest)
2021-03-02 17:47:22,226   16040    ERROR result.py(171) - 测试产生错误： test_login.test_login_demo (unittest.loader._FailedTest)
ImportError: Failed to import test module: test_login.test_login_demo
Traceback (most recent call last):
  File "D:\Anaconda3Install\lib\unittest\loader.py", line 436, in _find_test_path
    module = self._get_module_from_name(name)
  File "D:\Anaconda3Install\lib\unittest\loader.py", line 377, in _get_module_from_name
    __import__(name)
  File "D:\auto_saas_20210201\testcase\test_login\test_login_demo.py", line 14, in <module>
    class LoginDemo(unittest.TestCase):
  File "D:\auto_saas_20210201\testcase\test_login\test_login_demo.py", line 82, in LoginDemo
    @ddt.ddt(*parameter_data)
TypeError: ddt() takes from 0 to 1 positional arguments but 4 were given


2021-03-02 17:47:22,229   16040     INFO result.py(86) - 测试结束： test_login.test_login_demo (unittest.loader._FailedTest)
2021-03-02 17:47:22,229   16040     INFO result.py(87) - 耗时： 0.002987384796142578
2021-03-02 17:47:23,229   20404    ERROR test_runner.py(193) - 
Error	test_login.test_login_demo (unittest.loader._FailedTest)

2021-03-02 17:47:23,231   20404     INFO test_runner.py(211) - 
测试结束！
运行时间: 0:00:03.322896
共计执行用例数量：1
执行成功用例数量：0
执行失败用例数量：0
跳过执行用例数量：0
产生异常用例数量：1

