2021-03-01 17:48:57,540    1392     INFO test_runner.py(154) - 预计并发线程数：2
2021-03-01 17:48:59,616    6368     INFO result.py(65) - 开始测试： test_rejected (test_login.test_saas.MyTest)
2021-03-01 17:48:59,617    6368     INFO test_saas.py(10) - test
2021-03-01 17:49:04,733   20092     INFO result.py(65) - 开始测试： test_login_0_xyuer1019 (test_login.test_login_demo.LoginDemo)
2021-03-01 17:49:04,735   20092    ERROR result.py(171) - 测试产生错误： test_login_0_xyuer1019 (test_login.test_login_demo.LoginDemo)
Traceback (most recent call last):
  File "C:\Users\yu.zhang\AppData\Roaming\Python\Python38\site-packages\parameterized\parameterized.py", line 533, in standalone_func
    return func(*(a + p.args), **p.kwargs)
TypeError: test_login() missing 1 required positional argument: 'password'

2021-03-01 17:49:04,737   20092     INFO result.py(86) - 测试结束： test_login_0_xyuer1019 (test_login.test_login_demo.LoginDemo)
2021-03-01 17:49:04,737   20092     INFO result.py(87) - 耗时： 0.0029914379119873047
2021-03-01 17:49:04,738   20092     INFO result.py(65) - 开始测试： test_login_1_ (test_login.test_login_demo.LoginDemo)
2021-03-01 17:49:04,739   20092    ERROR result.py(171) - 测试产生错误： test_login_1_ (test_login.test_login_demo.LoginDemo)
Traceback (most recent call last):
  File "C:\Users\yu.zhang\AppData\Roaming\Python\Python38\site-packages\parameterized\parameterized.py", line 533, in standalone_func
    return func(*(a + p.args), **p.kwargs)
TypeError: test_login() missing 1 required positional argument: 'password'

2021-03-01 17:49:04,739   20092     INFO result.py(86) - 测试结束： test_login_1_ (test_login.test_login_demo.LoginDemo)
2021-03-01 17:49:04,739   20092     INFO result.py(87) - 耗时： 0.0009996891021728516
2021-03-01 17:49:10,322    6368     INFO test_saas.py(42) - 测试用例标题：双12活动打开1个宝箱
2021-03-01 17:49:10,447    6368     INFO HttpRequests.py(45) - post：https://pre.17kuxiu.com/user/getAnchorCoverAuditInfo
2021-03-01 17:49:10,447    6368     INFO HttpRequests.py(46) - 从请求到接口返回信息耗时：0.119104秒
2021-03-01 17:49:10,447    6368     INFO HttpRequests.py(26) - 接口返回数据：{"retCode":-100004,"retMsg":"头部信息不完整","success":false}
2021-03-01 17:49:10,449    6368    ERROR test_saas.py(52) - 失败：False is not true
2021-03-01 17:49:13,124    6368  WARNING result.py(186) - 测试未通过： test_rejected (test_login.test_saas.MyTest)
Traceback (most recent call last):
  File "D:\auto_saas_20210201\testcase\test_login\test_saas.py", line 49, in test_rejected
    self.assertTrue(r['retCode'] == 200)
AssertionError: False is not true

2021-03-01 17:49:13,125    6368     INFO result.py(86) - 测试结束： test_rejected (test_login.test_saas.MyTest)
2021-03-01 17:49:13,125    6368     INFO result.py(87) - 耗时： 13.507910013198853
2021-03-01 17:49:13,125    1392    ERROR test_runner.py(193) - 
Error	test_login_0_xyuer1019 (test_login.test_login_demo.LoginDemo)
Error	test_login_1_ (test_login.test_login_demo.LoginDemo)
Fail	test_rejected (test_login.test_saas.MyTest)

2021-03-01 17:49:13,127    1392     INFO test_runner.py(211) - 
测试结束！
运行时间: 0:00:16.890626
共计执行用例数量：3
执行成功用例数量：0
执行失败用例数量：1
跳过执行用例数量：0
产生异常用例数量：2

