2021-02-26 18:44:20,587   16148     INFO test_runner.py(154) - 预计并发线程数：2
2021-02-26 18:44:22,668   20936     INFO result.py(65) - 开始测试： test_rejected (test_login.test_saas.MyTest)
2021-02-26 18:44:22,669   20936     INFO test_saas.py(10) - test
2021-02-26 18:44:27,421    8536     INFO result.py(65) - 开始测试： test_login_00001 (test_login.test_login_demo.LoginDemo)
2021-02-26 18:44:32,251   20936     INFO test_saas.py(42) - 测试用例标题：双12活动打开1个宝箱
2021-02-26 18:44:32,319   20936     INFO HttpRequests.py(45) - post：https://pre.17kuxiu.com/user/getAnchorCoverAuditInfo
2021-02-26 18:44:32,320   20936     INFO HttpRequests.py(46) - 从请求到接口返回信息耗时：0.061635秒
2021-02-26 18:44:32,320   20936     INFO HttpRequests.py(26) - 接口返回数据：{"retCode":-100004,"retMsg":"头部信息不完整","success":false}
2021-02-26 18:44:32,320   20936    ERROR test_saas.py(52) - 失败：False is not true
2021-02-26 18:44:34,005    8536     INFO result.py(152) - 测试执行通过： test_login_00001 (test_login.test_login_demo.LoginDemo)
2021-02-26 18:44:34,005    8536     INFO result.py(86) - 测试结束： test_login_00001 (test_login.test_login_demo.LoginDemo)
2021-02-26 18:44:34,005    8536     INFO result.py(87) - 耗时： 6.582375526428223
2021-02-26 18:44:34,006    8536     INFO result.py(65) - 开始测试： test_login_00002 (test_login.test_login_demo.LoginDemo)
2021-02-26 18:44:34,711   20936  WARNING result.py(186) - 测试未通过： test_rejected (test_login.test_saas.MyTest)
Traceback (most recent call last):
  File "D:\auto_saas_20210201\testcase\test_login\test_saas.py", line 49, in test_rejected
    self.assertTrue(r['retCode'] == 200)
AssertionError: False is not true

2021-02-26 18:44:34,711   20936     INFO result.py(86) - 测试结束： test_rejected (test_login.test_saas.MyTest)
2021-02-26 18:44:34,711   20936     INFO result.py(87) - 耗时： 12.041302919387817
2021-02-26 18:44:39,202    8536     INFO result.py(152) - 测试执行通过： test_login_00002 (test_login.test_login_demo.LoginDemo)
2021-02-26 18:44:39,202    8536     INFO result.py(86) - 测试结束： test_login_00002 (test_login.test_login_demo.LoginDemo)
2021-02-26 18:44:39,203    8536     INFO result.py(87) - 耗时： 5.196394205093384
2021-02-26 18:44:39,203    8536     INFO result.py(65) - 开始测试： test_login_00003 (test_login.test_login_demo.LoginDemo)
2021-02-26 18:44:44,214    8536     INFO result.py(152) - 测试执行通过： test_login_00003 (test_login.test_login_demo.LoginDemo)
2021-02-26 18:44:44,215    8536     INFO result.py(86) - 测试结束： test_login_00003 (test_login.test_login_demo.LoginDemo)
2021-02-26 18:44:44,216    8536     INFO result.py(87) - 耗时： 5.01227879524231
2021-02-26 18:44:44,216    8536     INFO result.py(65) - 开始测试： test_login_00004 (test_login.test_login_demo.LoginDemo)
2021-02-26 18:44:49,203    8536     INFO result.py(152) - 测试执行通过： test_login_00004 (test_login.test_login_demo.LoginDemo)
2021-02-26 18:44:49,204    8536     INFO result.py(86) - 测试结束： test_login_00004 (test_login.test_login_demo.LoginDemo)
2021-02-26 18:44:49,204    8536     INFO result.py(87) - 耗时： 4.987923622131348
2021-02-26 18:44:52,888   16148     INFO test_runner.py(191) - 
Pass	test_login_00001 (test_login.test_login_demo.LoginDemo)	test_login_00001
Pass	test_login_00002 (test_login.test_login_demo.LoginDemo)	test_login_00002
Pass	test_login_00003 (test_login.test_login_demo.LoginDemo)	test_login_00003
Pass	test_login_00004 (test_login.test_login_demo.LoginDemo)	test_login_00004

2021-02-26 18:44:52,888   16148    ERROR test_runner.py(193) - 
Fail	test_rejected (test_login.test_saas.MyTest)

2021-02-26 18:44:52,891   16148     INFO test_runner.py(211) - 
测试结束！
运行时间: 0:00:33.550681
共计执行用例数量：5
执行成功用例数量：4
执行失败用例数量：1
跳过执行用例数量：0
产生异常用例数量：0

