2021-02-26 18:27:58,474    2872     INFO test_runner.py(154) - 预计并发线程数：2
2021-02-26 18:28:00,525   12692     INFO result.py(65) - 开始测试： test_rejected (test_login.test_saas.MyTest)
2021-02-26 18:28:00,526   12692     INFO test_saas.py(10) - test
2021-02-26 18:28:06,056   21556     INFO result.py(65) - 开始测试： test_login_00001 (test_login.test_login_demo.LoginDemo)
2021-02-26 18:28:06,058   21556    ERROR result.py(171) - 测试产生错误： test_login_00001 (test_login.test_login_demo.LoginDemo)
Traceback (most recent call last):
  File "C:\Users\yu.zhang\AppData\Roaming\Python\Python38\site-packages\ddt.py", line 182, in wrapper
    return func(self, *args, **kwargs)
TypeError: test_login() got an unexpected keyword argument 'Y'

2021-02-26 18:28:06,058   21556     INFO result.py(86) - 测试结束： test_login_00001 (test_login.test_login_demo.LoginDemo)
2021-02-26 18:28:06,059   21556     INFO result.py(87) - 耗时： 0.0009970664978027344
2021-02-26 18:28:06,059   21556     INFO result.py(65) - 开始测试： test_login_00002 (test_login.test_login_demo.LoginDemo)
2021-02-26 18:28:06,060   21556    ERROR result.py(171) - 测试产生错误： test_login_00002 (test_login.test_login_demo.LoginDemo)
Traceback (most recent call last):
  File "C:\Users\yu.zhang\AppData\Roaming\Python\Python38\site-packages\ddt.py", line 182, in wrapper
    return func(self, *args, **kwargs)
TypeError: test_login() got an unexpected keyword argument 'Y'

2021-02-26 18:28:06,060   21556     INFO result.py(86) - 测试结束： test_login_00002 (test_login.test_login_demo.LoginDemo)
2021-02-26 18:28:06,060   21556     INFO result.py(87) - 耗时： 0.0009968280792236328
2021-02-26 18:28:06,061   21556     INFO result.py(65) - 开始测试： test_login_00003 (test_login.test_login_demo.LoginDemo)
2021-02-26 18:28:06,061   21556    ERROR result.py(171) - 测试产生错误： test_login_00003 (test_login.test_login_demo.LoginDemo)
Traceback (most recent call last):
  File "C:\Users\yu.zhang\AppData\Roaming\Python\Python38\site-packages\ddt.py", line 182, in wrapper
    return func(self, *args, **kwargs)
TypeError: test_login() got an unexpected keyword argument 'Y'

2021-02-26 18:28:06,062   21556     INFO result.py(86) - 测试结束： test_login_00003 (test_login.test_login_demo.LoginDemo)
2021-02-26 18:28:06,062   21556     INFO result.py(87) - 耗时： 0.0009975433349609375
2021-02-26 18:28:06,062   21556     INFO result.py(65) - 开始测试： test_login_00004 (test_login.test_login_demo.LoginDemo)
2021-02-26 18:28:06,063   21556    ERROR result.py(171) - 测试产生错误： test_login_00004 (test_login.test_login_demo.LoginDemo)
Traceback (most recent call last):
  File "C:\Users\yu.zhang\AppData\Roaming\Python\Python38\site-packages\ddt.py", line 182, in wrapper
    return func(self, *args, **kwargs)
TypeError: test_login() got an unexpected keyword argument 'Y'

2021-02-26 18:28:06,063   21556     INFO result.py(86) - 测试结束： test_login_00004 (test_login.test_login_demo.LoginDemo)
2021-02-26 18:28:06,064   21556     INFO result.py(87) - 耗时： 0.0009968280792236328
2021-02-26 18:28:11,698   12692     INFO test_saas.py(42) - 测试用例标题：双12活动打开1个宝箱
2021-02-26 18:28:11,865   12692     INFO HttpRequests.py(45) - post：https://pre.17kuxiu.com/user/getAnchorCoverAuditInfo
2021-02-26 18:28:11,866   12692     INFO HttpRequests.py(46) - 从请求到接口返回信息耗时：0.157052秒
2021-02-26 18:28:11,866   12692     INFO HttpRequests.py(26) - 接口返回数据：{"retCode":-100004,"retMsg":"头部信息不完整","success":false}
2021-02-26 18:28:11,868   12692    ERROR test_saas.py(52) - 失败：False is not true
2021-02-26 18:28:15,264   12692  WARNING result.py(186) - 测试未通过： test_rejected (test_login.test_saas.MyTest)
Traceback (most recent call last):
  File "D:\auto_saas_20210201\testcase\test_login\test_saas.py", line 49, in test_rejected
    self.assertTrue(r['retCode'] == 200)
AssertionError: False is not true

2021-02-26 18:28:15,264   12692     INFO result.py(86) - 测试结束： test_rejected (test_login.test_saas.MyTest)
2021-02-26 18:28:15,264   12692     INFO result.py(87) - 耗时： 14.738372325897217
2021-02-26 18:28:15,264    2872    ERROR test_runner.py(193) - 
Error	test_login_00001 (test_login.test_login_demo.LoginDemo)	test_login_00001
Error	test_login_00002 (test_login.test_login_demo.LoginDemo)	test_login_00002
Error	test_login_00003 (test_login.test_login_demo.LoginDemo)	test_login_00003
Error	test_login_00004 (test_login.test_login_demo.LoginDemo)	test_login_00004
Fail	test_rejected (test_login.test_saas.MyTest)

2021-02-26 18:28:15,266    2872     INFO test_runner.py(211) - 
测试结束！
运行时间: 0:00:18.064519
共计执行用例数量：5
执行成功用例数量：0
执行失败用例数量：1
跳过执行用例数量：0
产生异常用例数量：4

