2021-03-01 14:34:13,332   10728     INFO test_runner.py(154) - 预计并发线程数：2
2021-03-01 14:34:15,347    2460     INFO result.py(65) - 开始测试： test_rejected (test_login.test_saas.MyTest)
2021-03-01 14:34:15,348    2460     INFO test_saas.py(10) - test
2021-03-01 14:34:20,617   19256     INFO result.py(65) - 开始测试： test_login_00001 (test_login.test_login_demo.LoginDemo)
2021-03-01 14:34:20,643   19256    ERROR result.py(171) - 测试产生错误： test_login_00001 (test_login.test_login_demo.LoginDemo)
Traceback (most recent call last):
  File "C:\Users\yu.zhang\AppData\Roaming\Python\Python38\site-packages\ddt.py", line 182, in wrapper
    return func(self, *args, **kwargs)
  File "D:\auto_saas_20210201\testcase\test_login\test_login_demo.py", line 57, in test_login
    self.login(*args, **kwargs)
TypeError: login() got an unexpected keyword argument 'case'

2021-03-01 14:34:20,643   19256     INFO result.py(86) - 测试结束： test_login_00001 (test_login.test_login_demo.LoginDemo)
2021-03-01 14:34:20,643   19256     INFO result.py(87) - 耗时： 0.024933576583862305
2021-03-01 14:34:20,644   19256     INFO result.py(65) - 开始测试： test_login_00002 (test_login.test_login_demo.LoginDemo)
2021-03-01 14:34:20,645   19256    ERROR result.py(171) - 测试产生错误： test_login_00002 (test_login.test_login_demo.LoginDemo)
Traceback (most recent call last):
  File "C:\Users\yu.zhang\AppData\Roaming\Python\Python38\site-packages\ddt.py", line 182, in wrapper
    return func(self, *args, **kwargs)
  File "D:\auto_saas_20210201\testcase\test_login\test_login_demo.py", line 57, in test_login
    self.login(*args, **kwargs)
TypeError: login() got an unexpected keyword argument 'case'

2021-03-01 14:34:20,645   19256     INFO result.py(86) - 测试结束： test_login_00002 (test_login.test_login_demo.LoginDemo)
2021-03-01 14:34:20,645   19256     INFO result.py(87) - 耗时： 0.0009975433349609375
2021-03-01 14:34:20,645   19256     INFO result.py(65) - 开始测试： test_login_00003 (test_login.test_login_demo.LoginDemo)
2021-03-01 14:34:20,646   19256    ERROR result.py(171) - 测试产生错误： test_login_00003 (test_login.test_login_demo.LoginDemo)
Traceback (most recent call last):
  File "C:\Users\yu.zhang\AppData\Roaming\Python\Python38\site-packages\ddt.py", line 182, in wrapper
    return func(self, *args, **kwargs)
  File "D:\auto_saas_20210201\testcase\test_login\test_login_demo.py", line 57, in test_login
    self.login(*args, **kwargs)
TypeError: login() got an unexpected keyword argument 'case'

2021-03-01 14:34:20,647   19256     INFO result.py(86) - 测试结束： test_login_00003 (test_login.test_login_demo.LoginDemo)
2021-03-01 14:34:20,647   19256     INFO result.py(87) - 耗时： 0.0009829998016357422
2021-03-01 14:34:20,647   19256     INFO result.py(65) - 开始测试： test_login_00004 (test_login.test_login_demo.LoginDemo)
2021-03-01 14:34:20,648   19256    ERROR result.py(171) - 测试产生错误： test_login_00004 (test_login.test_login_demo.LoginDemo)
Traceback (most recent call last):
  File "C:\Users\yu.zhang\AppData\Roaming\Python\Python38\site-packages\ddt.py", line 182, in wrapper
    return func(self, *args, **kwargs)
  File "D:\auto_saas_20210201\testcase\test_login\test_login_demo.py", line 57, in test_login
    self.login(*args, **kwargs)
TypeError: login() got an unexpected keyword argument 'case'

2021-03-01 14:34:20,649   19256     INFO result.py(86) - 测试结束： test_login_00004 (test_login.test_login_demo.LoginDemo)
2021-03-01 14:34:20,649   19256     INFO result.py(87) - 耗时： 0.0
2021-03-01 14:34:26,621    2460     INFO test_saas.py(42) - 测试用例标题：双12活动打开1个宝箱
2021-03-01 14:34:26,771    2460     INFO HttpRequests.py(45) - post：https://pre.17kuxiu.com/user/getAnchorCoverAuditInfo
2021-03-01 14:34:26,771    2460     INFO HttpRequests.py(46) - 从请求到接口返回信息耗时：0.143277秒
2021-03-01 14:34:26,771    2460     INFO HttpRequests.py(26) - 接口返回数据：{"retCode":-100004,"retMsg":"头部信息不完整","success":false}
2021-03-01 14:34:26,772    2460    ERROR test_saas.py(52) - 失败：False is not true
2021-03-01 14:34:29,571    2460  WARNING result.py(186) - 测试未通过： test_rejected (test_login.test_saas.MyTest)
Traceback (most recent call last):
  File "D:\auto_saas_20210201\testcase\test_login\test_saas.py", line 49, in test_rejected
    self.assertTrue(r['retCode'] == 200)
AssertionError: False is not true

2021-03-01 14:34:29,572    2460     INFO result.py(86) - 测试结束： test_rejected (test_login.test_saas.MyTest)
2021-03-01 14:34:29,572    2460     INFO result.py(87) - 耗时： 14.223653554916382
2021-03-01 14:34:29,572   10728    ERROR test_runner.py(193) - 
Error	test_login_00001 (test_login.test_login_demo.LoginDemo)	test_login_00001
Error	test_login_00002 (test_login.test_login_demo.LoginDemo)	test_login_00002
Error	test_login_00003 (test_login.test_login_demo.LoginDemo)	test_login_00003
Error	test_login_00004 (test_login.test_login_demo.LoginDemo)	test_login_00004
Fail	test_rejected (test_login.test_saas.MyTest)

2021-03-01 14:34:29,576   10728     INFO test_runner.py(211) - 
测试结束！
运行时间: 0:00:17.614972
共计执行用例数量：5
执行成功用例数量：0
执行失败用例数量：1
跳过执行用例数量：0
产生异常用例数量：4

