2021-03-02 16:12:47,955   16304     INFO test_runner.py(154) - 预计并发线程数：2
2021-03-02 16:12:50,055    2608     INFO result.py(65) - 开始测试： test_rejected (test_login.test_saas.MyTest)
2021-03-02 16:12:50,055    2608     INFO test_saas.py(10) - test
2021-03-02 16:12:55,081     248     INFO result.py(65) - 开始测试： test_login_00001_test_login_demo (test_login.test_login_demo.LoginDemo)
2021-03-02 16:12:55,110     248    ERROR result.py(171) - 测试产生错误： test_login_00001_test_login_demo (test_login.test_login_demo.LoginDemo)
Traceback (most recent call last):
  File "C:\Users\yu.zhang\AppData\Roaming\Python\Python38\site-packages\ddt.py", line 182, in wrapper
    return func(self, *args, **kwargs)
TypeError: test_login() missing 2 required positional arguments: 'username' and 'password'

2021-03-02 16:12:55,110     248     INFO result.py(86) - 测试结束： test_login_00001_test_login_demo (test_login.test_login_demo.LoginDemo)
2021-03-02 16:12:55,111     248     INFO result.py(87) - 耗时： 0.028923749923706055
2021-03-02 16:12:55,111     248     INFO result.py(65) - 开始测试： test_login_00002_AccessToken (test_login.test_login_demo.LoginDemo)
2021-03-02 16:12:55,112     248    ERROR result.py(171) - 测试产生错误： test_login_00002_AccessToken (test_login.test_login_demo.LoginDemo)
Traceback (most recent call last):
  File "C:\Users\yu.zhang\AppData\Roaming\Python\Python38\site-packages\ddt.py", line 182, in wrapper
    return func(self, *args, **kwargs)
TypeError: test_login() got an unexpected keyword argument 'token1'

2021-03-02 16:12:55,112     248     INFO result.py(86) - 测试结束： test_login_00002_AccessToken (test_login.test_login_demo.LoginDemo)
2021-03-02 16:12:55,113     248     INFO result.py(87) - 耗时： 0.0009965896606445312
2021-03-02 16:12:55,113     248     INFO result.py(65) - 开始测试： test_login_00003_AppInfo (test_login.test_login_demo.LoginDemo)
2021-03-02 16:12:55,114     248    ERROR result.py(171) - 测试产生错误： test_login_00003_AppInfo (test_login.test_login_demo.LoginDemo)
Traceback (most recent call last):
  File "C:\Users\yu.zhang\AppData\Roaming\Python\Python38\site-packages\ddt.py", line 182, in wrapper
    return func(self, *args, **kwargs)
TypeError: test_login() got an unexpected keyword argument 'secretkey'

2021-03-02 16:12:55,114     248     INFO result.py(86) - 测试结束： test_login_00003_AppInfo (test_login.test_login_demo.LoginDemo)
2021-03-02 16:12:55,114     248     INFO result.py(87) - 耗时： 0.0009982585906982422
2021-03-02 16:12:55,115     248     INFO result.py(65) - 开始测试： test_login_00004_MobileInfo (test_login.test_login_demo.LoginDemo)
2021-03-02 16:12:55,115     248    ERROR result.py(171) - 测试产生错误： test_login_00004_MobileInfo (test_login.test_login_demo.LoginDemo)
Traceback (most recent call last):
  File "C:\Users\yu.zhang\AppData\Roaming\Python\Python38\site-packages\ddt.py", line 182, in wrapper
    return func(self, *args, **kwargs)
TypeError: test_login() got an unexpected keyword argument 'imei'

2021-03-02 16:12:55,116     248     INFO result.py(86) - 测试结束： test_login_00004_MobileInfo (test_login.test_login_demo.LoginDemo)
2021-03-02 16:12:55,116     248     INFO result.py(87) - 耗时： 0.0009958744049072266
2021-03-02 16:12:55,116     248     INFO result.py(65) - 开始测试： test_login_00005_TestAccount (test_login.test_login_demo.LoginDemo)
2021-03-02 16:12:55,117     248    ERROR result.py(171) - 测试产生错误： test_login_00005_TestAccount (test_login.test_login_demo.LoginDemo)
Traceback (most recent call last):
  File "C:\Users\yu.zhang\AppData\Roaming\Python\Python38\site-packages\ddt.py", line 182, in wrapper
    return func(self, *args, **kwargs)
TypeError: test_login() got an unexpected keyword argument 'mobile'

2021-03-02 16:12:55,118     248     INFO result.py(86) - 测试结束： test_login_00005_TestAccount (test_login.test_login_demo.LoginDemo)
2021-03-02 16:12:55,118     248     INFO result.py(87) - 耗时： 0.00099945068359375
2021-03-02 16:13:00,794    2608     INFO test_saas.py(42) - 测试用例标题：双12活动打开1个宝箱
2021-03-02 16:13:01,163    2608     INFO HttpRequests.py(45) - post：https://pre.17kuxiu.com/user/getAnchorCoverAuditInfo
2021-03-02 16:13:01,163    2608     INFO HttpRequests.py(46) - 从请求到接口返回信息耗时：0.36157秒
2021-03-02 16:13:01,163    2608     INFO HttpRequests.py(26) - 接口返回数据：{"retCode":-100004,"retMsg":"头部信息不完整","success":false}
2021-03-02 16:13:01,164    2608    ERROR test_saas.py(52) - 失败：False is not true
2021-03-02 16:13:04,203    2608  WARNING result.py(186) - 测试未通过： test_rejected (test_login.test_saas.MyTest)
Traceback (most recent call last):
  File "D:\auto_saas_20210201\testcase\test_login\test_saas.py", line 49, in test_rejected
    self.assertTrue(r['retCode'] == 200)
AssertionError: False is not true

2021-03-02 16:13:04,204    2608     INFO result.py(86) - 测试结束： test_rejected (test_login.test_saas.MyTest)
2021-03-02 16:13:04,204    2608     INFO result.py(87) - 耗时： 14.149311304092407
2021-03-02 16:13:04,204   16304    ERROR test_runner.py(193) - 
Error	test_login_00001_test_login_demo (test_login.test_login_demo.LoginDemo)	test_login_00001_test_login_demo
Error	test_login_00002_AccessToken (test_login.test_login_demo.LoginDemo)	test_login_00002_AccessToken
Error	test_login_00003_AppInfo (test_login.test_login_demo.LoginDemo)	test_login_00003_AppInfo
Error	test_login_00004_MobileInfo (test_login.test_login_demo.LoginDemo)	test_login_00004_MobileInfo
Error	test_login_00005_TestAccount (test_login.test_login_demo.LoginDemo)	test_login_00005_TestAccount
Fail	test_rejected (test_login.test_saas.MyTest)

2021-03-02 16:13:04,207   16304     INFO test_runner.py(211) - 
测试结束！
运行时间: 0:00:17.465531
共计执行用例数量：6
执行成功用例数量：0
执行失败用例数量：1
跳过执行用例数量：0
产生异常用例数量：5

